<?xml version="1.0" ?>
<!-- =================================================================================== -->
<!-- |    This document was autogenerated by xacro from /home/a/ws_nhk/src/arm_v20_description-20251026T114629Z-1-001/arm_v20_description/urdf/arm_v20.xacro | -->
<!-- |    EDITING THIS FILE BY HAND IS NOT RECOMMENDED                                 | -->
<!-- =================================================================================== -->
<robot name="arm_v20">
  <material name="silver_default">
    <color rgba="0.700 0.700 0.700 1.000"/>
  </material>
  <material name="opaque202209238">
    <color rgba="0.792156862745098 0.8196078431372549 0.9333333333333333 1.0"/>
  </material>
  <material name="steel_satin">
    <color rgba="0.6274509803921569 0.6274509803921569 0.6274509803921569 1.0"/>
  </material>
  <transmission name="Revolute 1_tran">
    <type>transmission_interface/SimpleTransmission</type>
    <joint name="Revolute 1">
      <hardwareInterface>hardware_interface/EffortJointInterface</hardwareInterface>
    </joint>
    <actuator name="Revolute 1_actr">
      <hardwareInterface>hardware_interface/EffortJointInterface</hardwareInterface>
      <mechanicalReduction>1</mechanicalReduction>
    </actuator>
  </transmission>
  <transmission name="Revolute 2_tran">
    <type>transmission_interface/SimpleTransmission</type>
    <joint name="Revolute 2">
      <hardwareInterface>hardware_interface/EffortJointInterface</hardwareInterface>
    </joint>
    <actuator name="Revolute 2_actr">
      <hardwareInterface>hardware_interface/EffortJointInterface</hardwareInterface>
      <mechanicalReduction>1</mechanicalReduction>
    </actuator>
  </transmission>
  <transmission name="Revolute 3_tran">
    <type>transmission_interface/SimpleTransmission</type>
    <joint name="Revolute 3">
      <hardwareInterface>hardware_interface/EffortJointInterface</hardwareInterface>
    </joint>
    <actuator name="Revolute 3_actr">
      <hardwareInterface>hardware_interface/EffortJointInterface</hardwareInterface>
      <mechanicalReduction>1</mechanicalReduction>
    </actuator>
  </transmission>
  <transmission name="Revolute 4_tran">
    <type>transmission_interface/SimpleTransmission</type>
    <joint name="Revolute 4">
      <hardwareInterface>hardware_interface/EffortJointInterface</hardwareInterface>
    </joint>
    <actuator name="Revolute 4_actr">
      <hardwareInterface>hardware_interface/EffortJointInterface</hardwareInterface>
      <mechanicalReduction>1</mechanicalReduction>
    </actuator>
  </transmission>
  <transmission name="Revolute 5_tran">
    <type>transmission_interface/SimpleTransmission</type>
    <joint name="Revolute 5">
      <hardwareInterface>hardware_interface/EffortJointInterface</hardwareInterface>
    </joint>
    <actuator name="Revolute 5_actr">
      <hardwareInterface>hardware_interface/EffortJointInterface</hardwareInterface>
      <mechanicalReduction>1</mechanicalReduction>
    </actuator>
  </transmission>
  <transmission name="Revolute 6_tran">
    <type>transmission_interface/SimpleTransmission</type>
    <joint name="Revolute 6">
      <hardwareInterface>hardware_interface/EffortJointInterface</hardwareInterface>
    </joint>
    <actuator name="Revolute 6_actr">
      <hardwareInterface>hardware_interface/EffortJointInterface</hardwareInterface>
      <mechanicalReduction>1</mechanicalReduction>
    </actuator>
  </transmission>
  <link name="base_link">
    <inertial>
      <origin rpy="0 0 0" xyz="-0.022278248739678576 2.202100536240091e-05 0.024368049710172035"/>
      <mass value="4.587257651065842"/>
      <inertia ixx="0.011004" ixy="2.1e-05" ixz="-0.001934" iyy="0.018642" iyz="-3e-06" izz="0.023201"/>
    </inertial>
    <visual>
      <origin rpy="0 0 0" xyz="0 0 0"/>
      <geometry>
        <mesh filename="package://arm_v20_description/meshes/base_link.stl" scale="0.001 0.001 0.001"/>
      </geometry>
      <material name="silver_default"/>
    </visual>
    <collision>
      <origin rpy="0 0 0" xyz="0 0 0"/>
      <geometry>
        <mesh filename="package://arm_v20_description/meshes/base_link.stl" scale="0.001 0.001 0.001"/>
      </geometry>
    </collision>
  </link>
  <link name="link1_1">
    <inertial>
      <origin rpy="0 0 0" xyz="9.624761041591018e-05 0.0004766171386192786 0.04186909675865289"/>
      <mass value="0.9838737385924954"/>
      <inertia ixx="0.000872" ixy="0.0" ixz="1e-06" iyy="0.000818" iyz="-8e-06" izz="0.000427"/>
    </inertial>
    <visual>
      <origin rpy="0 0 0" xyz="-0.0 0.0 -0.0525"/>
      <geometry>
        <mesh filename="package://arm_v20_description/meshes/link1_1.stl" scale="0.001 0.001 0.001"/>
      </geometry>
      <material name="opaque202209238"/>
    </visual>
    <collision>
      <origin rpy="0 0 0" xyz="-0.0 0.0 -0.0525"/>
      <geometry>
        <mesh filename="package://arm_v20_description/meshes/link1_1.stl" scale="0.001 0.001 0.001"/>
      </geometry>
    </collision>
  </link>
  <link name="link2_1">
    <inertial>
      <origin rpy="0 0 0" xyz="0.010133653025085067 -0.030787540537666767 0.10364955203955004"/>
      <mass value="1.224302434218257"/>
      <inertia ixx="0.003371" ixy="6.3e-05" ixz="-0.000481" iyy="0.003402" iyz="0.000295" izz="0.000694"/>
    </inertial>
    <visual>
      <origin rpy="0 0 0" xyz="-2.1e-05 -0.024521 -0.123563"/>
      <geometry>
        <mesh filename="package://arm_v20_description/meshes/link2_1.stl" scale="0.001 0.001 0.001"/>
      </geometry>
      <material name="opaque202209238"/>
    </visual>
    <collision>
      <origin rpy="0 0 0" xyz="-2.1e-05 -0.024521 -0.123563"/>
      <geometry>
        <mesh filename="package://arm_v20_description/meshes/link2_1.stl" scale="0.001 0.001 0.001"/>
      </geometry>
    </collision>
  </link>
  <link name="link3_1">
    <inertial>
      <origin rpy="0 0 0" xyz="0.0767579948374143 -0.020345095492947766 -1.1714610781421442e-08"/>
      <mass value="0.7543922108135824"/>
      <inertia ixx="0.000301" ixy="-0.000236" ixz="0.0" iyy="0.001471" iyz="0.0" izz="0.001623"/>
    </inertial>
    <visual>
      <origin rpy="0 0 0" xyz="-0.034771 -0.012321 -0.265313"/>
      <geometry>
        <mesh filename="package://arm_v20_description/meshes/link3_1.stl" scale="0.001 0.001 0.001"/>
      </geometry>
      <material name="steel_satin"/>
    </visual>
    <collision>
      <origin rpy="0 0 0" xyz="-0.034771 -0.012321 -0.265313"/>
      <geometry>
        <mesh filename="package://arm_v20_description/meshes/link3_1.stl" scale="0.001 0.001 0.001"/>
      </geometry>
    </collision>
  </link>
  <link name="link4_1">
    <inertial>
      <origin rpy="0 0 0" xyz="0.0407741110945509 -0.004894497498326476 -4.247916734145818e-06"/>
      <mass value="1.0144724963260483"/>
      <inertia ixx="0.000321" ixy="-0.000103" ixz="0.0" iyy="0.000784" iyz="0.0" izz="0.000827"/>
    </inertial>
    <visual>
      <origin rpy="0 0 0" xyz="-0.170171 0.000179 -0.265313"/>
      <geometry>
        <mesh filename="package://arm_v20_description/meshes/link4_1.stl" scale="0.001 0.001 0.001"/>
      </geometry>
      <material name="silver_default"/>
    </visual>
    <collision>
      <origin rpy="0 0 0" xyz="-0.170171 0.000179 -0.265313"/>
      <geometry>
        <mesh filename="package://arm_v20_description/meshes/link4_1.stl" scale="0.001 0.001 0.001"/>
      </geometry>
    </collision>
  </link>
  <link name="link5_1">
    <inertial>
      <origin rpy="0 0 0" xyz="0.04474344188385446 0.018892728314517836 -0.0113461510891818"/>
      <mass value="0.4401808093617498"/>
      <inertia ixx="0.000133" ixy="0.0" ixz="5e-06" iyy="0.00014" iyz="0.0" izz="0.000129"/>
    </inertial>
    <visual>
      <origin rpy="0 0 0" xyz="-0.248771 0.019079 -0.265313"/>
      <geometry>
        <mesh filename="package://arm_v20_description/meshes/link5_1.stl" scale="0.001 0.001 0.001"/>
      </geometry>
      <material name="silver_default"/>
    </visual>
    <collision>
      <origin rpy="0 0 0" xyz="-0.248771 0.019079 -0.265313"/>
      <geometry>
        <mesh filename="package://arm_v20_description/meshes/link5_1.stl" scale="0.001 0.001 0.001"/>
      </geometry>
    </collision>
  </link>
  <link name="endeffector_1">
    <inertial>
      <origin rpy="0 0 0" xyz="0.08904032725072031 1.462168207331106e-05 0.00266069074925096"/>
      <mass value="2.250858835490703"/>
      <inertia ixx="0.002403" ixy="-3e-06" ixz="0.000385" iyy="0.00715" iyz="-2e-06" izz="0.006731"/>
    </inertial>
    <visual>
      <origin rpy="0 0 0" xyz="-0.313771 0.000179 -0.265313"/>
      <geometry>
        <mesh filename="package://arm_v20_description/meshes/endeffector_1.stl" scale="0.001 0.001 0.001"/>
      </geometry>
      <material name="silver_default"/>
    </visual>
    <collision>
      <origin rpy="0 0 0" xyz="-0.313771 0.000179 -0.265313"/>
      <geometry>
        <mesh filename="package://arm_v20_description/meshes/endeffector_1.stl" scale="0.001 0.001 0.001"/>
      </geometry>
    </collision>
  </link>
  <joint name="Revolute 1" type="continuous">
    <origin rpy="0 0 0" xyz="0.0 0.0 0.0525"/>
    <parent link="base_link"/>
    <child link="link1_1"/>
    <axis xyz="-0.0 -0.0 1.0"/>
  </joint>
  <joint name="Revolute 2" type="revolute">
    <origin rpy="0 0 0" xyz="2.1e-05 0.024521 0.071063"/>
    <parent link="link1_1"/>
    <child link="link2_1"/>
    <axis xyz="0.0 1.0 -0.0"/>
    <limit effort="100" lower="-1.570796" upper="1.570796" velocity="100"/>
  </joint>
  <joint name="Revolute 3" type="revolute">
    <origin rpy="0 0 0" xyz="0.03475 -0.0122 0.14175"/>
    <parent link="link2_1"/>
    <child link="link3_1"/>
    <axis xyz="0.0 1.0 -0.0"/>
    <limit effort="100" lower="-1.570796" upper="1.570796" velocity="100"/>
  </joint>
  <joint name="Revolute 4" type="continuous">
    <origin rpy="0 0 0" xyz="0.1354 -0.0125 0.0"/>
    <parent link="link3_1"/>
    <child link="link4_1"/>
    <axis xyz="1.0 -0.0 -0.0"/>
  </joint>
  <joint name="Revolute 5" type="revolute">
    <origin rpy="0 0 0" xyz="0.0786 -0.0189 0.0"/>
    <parent link="link4_1"/>
    <child link="link5_1"/>
    <axis xyz="0.0 1.0 -0.0"/>
    <limit effort="100" lower="-1.570796" upper="3.141592" velocity="100"/>
  </joint>
  <joint name="Revolute 6" type="continuous">
    <origin rpy="0 0 0" xyz="0.065 0.0189 0.0"/>
    <parent link="link5_1"/>
    <child link="endeffector_1"/>
    <axis xyz="1.0 -0.0 -0.0"/>
  </joint>
</robot>
